<robot name="mycar">
    <link name="base_link">
        <visual>
            <!-- 形状 -->
            <geometry>
                <!-- 长方体的长宽高 -->
                <box size="0.5 0.3 0.1" />
                <!-- 圆柱，半径和长度 -->
                <!-- <cylinder radius="0.5" length="0.1" /> -->
                <!-- 球体，半径-->
                <!-- <sphere radius="0.3" /> -->

            </geometry>
            <!-- xyz坐标 rpy翻滚俯仰与偏航角度(3.14=180度 1.57=90度) -->
            <origin xyz="0 0 0.05" rpy="0 0 0" />
            <!-- 颜色: r=red g=green b=blue a=alpha -->
            <material name="black">
                <color rgba="0.7 0.5 0 0.5" />
            </material>
        </visual>
    </link>
    <link name="camera">
        <visual>
            <!-- 形状 -->
            <geometry>
                <!-- 长方体的长宽高 -->
                <box size="0.02 0.05 0.05" />
                <!-- 圆柱，半径和长度 -->
                <!-- <cylinder radius="0.5" length="0.1" /> -->
                <!-- 球体，半径-->
                <!-- <sphere radius="0.3" /> -->

            </geometry>
            <!-- xyz坐标 rpy翻滚俯仰与偏航角度(3.14=180度 1.57=90度) -->
            <origin xyz="0 0 0.025" rpy="0 0 0" />
            <!-- 颜色: r=red g=green b=blue a=alpha -->
            <material name="camera_color">
                <color rgba="0.2 0.2 1 0.5" />
            </material>
        </visual>
    </link>
    <joint name="camera2base" type="continuous">
        <parent link="base_link"/>
        <child link="camera"/>
        <origin xyz="0.2 0 0.05" rpy="0 0 0"/>
        <axis xyz="0 0 1"/>
    </joint>
</robot>